Workbook

Sheet Transactions
A1: txn_date | B1: description | C1: amount | D1: category | E1: note
A2: 01/09/2025 | B2: Mlinar | C2: -3.36 | D2: Dining & Restaurants
A3: 01/09/2025 | B3: Plodine | C3: -2.76 | D3: Groceries
A4: 01/09/2025 | B4: Naplata naknade za vođenje računa | C4: -3 | D4: Other
A5: 01/09/2025 | B5: U17357273 Dmytro Semeniuk | C5: -50 | D5: Investments
A6: 01/09/2025 | B6: Lidl | C6: -4.86 | D6: Groceries
A7: 02/09/2025 | B7: INA | C7: -20.01 | D7: Transportation
A8: 02/09/2025 | B8: SPAR Food & Fuel | C8: -0.85 | D8: Groceries
A9: 03/09/2025 | B9: AliExpress | C9: -8.64 | D9: Groceries
A10: 04/09/2025 | B10: Chatgpt | C10: -18.4 | D10: Entertainment & Subscriptions
A11: 05/09/2025 | B11: GOOGLE *YouTubePremium | C11: -3.06 | D11: Entertainment & Subscriptions
A12: 05/09/2025 | B12: UBER * EATS PENDING | C12: -18.64 | D12: Travelling
A13: 06/09/2025 | B13: PRTMN *KYIVSTAR T | C13: -2.05 | D13: Other
... A21: 15/09/2025 | B21: Bmove | C21: -0.6 | D21: Transportation
A22: 15/09/2025 | B22: Pu51000rijeka | C22: -15.5 | D22: Other | E22: Посилка словенцу
A23: 15/09/2025 | B23: Dante Bar | C23: -2.3 | D23: Coffee
A24: 15/09/2025 | B24: FlixBus | C24: -25.98 | D24: Travelling
A25: 15/09/2025 | B25: SPAR Food & Fuel | C25: -1.58 | D25: Groceries
A26: 15/09/2025 | B26: SPAR Food & Fuel | C26: -2.94 | D26: Groceries
A27: 16/09/2025 | B27: Restoran Kampus | C27: -1.88 | D27: Dining & Restaurants
A28: 17/09/2025 | B28: Mlinar | C28: -1.3 | D28: Dining & Restaurants
A29: 17/09/2025 | B29: Restoran Kampus | C29: -1.41 | D29: Dining & Restaurants
A30: 17/09/2025 | B30: Airbnb | C30: =-258.75/3 -> -86.25 | D30: Travelling | E30: Житло
A31: 17/09/2025 | B31: Gavranović | C31: -1.49 | D31: Groceries
A32: 17/09/2025 | B32: INA | C32: -20.08 | D32: Transportation
A33: 18/09/2025 | B33: Bmove | C33: -1 | D33: Transportation
A34: 19/09/2025 | B34: Gavranović | C34: -2.79 | D34: Groceries
A35: 19/09/2025 | B35: Plodine | C35: -0.44 | D35: Groceries
A36: 19/09/2025 | B36: Restoran Kampus | C36: -0.95 | D36: Dining & Restaurants
A37: 19/09/2025 | B37: dm drogerie | C37: -1.75 | D37: Other
A38: 20/09/2025 | B38: Rijeka Trans | C38: -30.02 | D38: Transportation
A39: 20/09/2025 | B39: KEKS Pay | C39: -2.3 | D39: Coffee
A40: 20/09/2025 | B40: SPAR Food & Fuel | C40: -1.09 | D40: Groceries
A41: 21/09/2025 | B41: Arriva | C41: -11.1 | D41: Travelling
A42: 22/09/2025 | B42: Transfer to ARTUR NASIROV | C42: -1 | D42: Other
... A54: 24/09/2025 | B54: Spar | C54: -2.44 | D54: Travelling
A55: 24/09/2025 | B55: Starbucks | C55: =-18.65/3 -> -6.2166667 | D55: Travelling
A56: 24/09/2025 | B56: Spar | C56: -2.1 | D56: Travelling
A57: 24/09/2025 | B57: Manna ABC | C57: -2.44 | D57: Travelling
A58: 25/09/2025 | B58: Noiret Biliárd & Darts Szalon | C58: =-11.72/2 -> -5.86 | D58: Travelling
...

Sheet Stats
A1: CASH | B1: 680
A2: ERSTE | B2: 92
A3: REVOLUT | B3: 168
A4: MONOBANK | B4: 0
A6: STOCKS INVESTMENTS | B6: 395
A7: CRYPTO INVESTMENTS | B7: 1052
A8: EMERGENCY FUND | B8: 400
A9: Savings | B9: 800 | C9: 200 євро на бінанс
A12: SPENT BY CATEGORIES
A13: Groceries | B13: =SUMIF(Table1[category],Stats!A13,Table1[amount]) -> -45.47
A14: Transportation | B14: =SUMIF(Table1[category],Stats!A14,Table1[amount]) -> -93.51
A15: Coffee | B15: =SUMIF(Table1[category],Stats!A15,Table1[amount]) -> -27.8
A16: Dining & Restaurants | B16: =SUMIF(Table1[category],Stats!A16,Table1[amount]) -> -23.93
A17: Shopping | B17: =SUMIF(Table1[category],Stats!A17,Table1[amount]) -> 0
A18: Home | B18: =SUMIF(Table1[category],Stats!A18,Table1[amount]) -> 0
A19: Cash Withdrawals | B19: =SUMIF(Table1[category],Stats!A19,Table1[amount]) -> 0
A20: Entertainment & Subscriptions | B20: =SUMIF(Table1[category],Stats!A20,Table1[amount]) -> -30.94
A21: Travelling | B21: =SUMIF(Table1[category],Stats!A21,Table1[amount]) -> -282.83167
A22: Education & Studying | B22: =SUMIF(Table1[category],Stats!A22,Table1[amount]) -> 0
A23: Other | B23: =SUMIF(Table1[category],Stats!A23,Table1[amount]) -> -44.1
A24: Investments | B24: =SUMIF(Table1[category],Stats!A24,Table1[amount]) -> -50
A26: Income | B26: =SUMIF(Table1[category],Stats!A26,Table1[amount]) -> 0
B27: =SUM(B13:B24) -> -598.58167
